model
size = 7 12 13
scale = 0.075
origin = -y
rotation = 40 0 0
position = 0 -0.08 -0.25
ao = 5 3
material lighting = smooth, roughness = 0.25, metalness = 0.25, fade = true, deform = 10
  colors = A:#F00 B:#C00
material lighting = smooth, roughness = 0.5, metalness = 0, fade = true, deform = 3
  colors = C:#F00 D:#0A0 E:#963
voxels
------- ---B--- --BBB-- --BBB-- --AAA-- ------- ------- ------- ------- ------- ------- ------- 
--BBB-- --BBB-- -BBBBB- -BBBBB- -AAAAA- -BBBBB- ------- ------- ------- ------- ------- ------- 
-BB-BB- -BBBBB- BBBBBBB BBBBBBB AA---AA -B---B- ------- ------- ------- ------- ------- ------- 
-B---B- BBB-BBB BBBCBBB BBBCBBB AA-D-AA -B-D-B- ---D--- ---D--- ---EE-- ---EE-- ------- ------- 
-BB-BB- -BBBBB- BBBBBBB BBBBBBB AA---AA -B---B- ------- ------- ---D--- ------- ------- ------- 
--BBB-- --BBB-- -BBBBB- -BBBBB- -AAAAA- -BBBBB- ------- ------- ---D--- ------- ------- ------- 
------- ---B--- --BBB-- --BBB-- --AAA-- ------- ------- ------- ---D--- ------- ------- ------- 
------- ------- ------- ------- ------- ------- -BBBBB- -B---B- -B-D-B- -B---B- -BBBBB- -------
------- ------- ------- ------- ------- --AAA-- -AAAAA- AA---AA AA-D-AA AA---AA -AAAAA- --AAA--
------- ------- ------- ------- ------- --BBB-- -BBBBB- BBBBBBB BBBCBBB BBBBBBB -BBBBB- --BBB--
------- ------- ------- ------- ------- --BBB-- -BBBBB- BBBBBBB BBBCBBB BBBBBBB -BBBBB- --BBB--
------- ------- ------- ------- ------- ---B--- --BBB-- -BBBBB- BBB-BBB -BBBBB- --BBB-- ---B--- 
------- ------- ------- ------- ------- ------- --BBB-- -BB-BB- -B---B- -BB-BB- --BBB-- -------