model
size = 7 10 7
scale = 0.03
origin = -y
shape = cylinder-y
ao = 1 0.75
material lighting = both
  colors = A:#444
material lighting = smooth
  colors = R:#F00 B:#00F D:#222
voxels
AAAAAAA AAAAAAA AAAAAAA AAAAAAA AAAAAAA AAAAAAA AAAAAAA ------- ------- -------
AAAAAAA A-R-B-A A-R-B-A A-R-B-A A-R-B-A A-R-B-A A-R-B-A --R-B-- --R-B-- --R-B--
AAAAAAA A-----A A-----A A-----A A-----A A-----A A-----A ------- ------- -------
AAAAAAA A-----A A-----A A-----A A-----A A-----A A----BA -----B- -----B- -----B-
AAAAAAA A-----A A-----A A-----A A-----A A-----A A-----A ------- ------- -------
AAAAAAA A-D---A A-D---A A-D---A A-D---A A-D---A A-D---A --D---- --D---- --D----
AAAAAAA AAAAAAA AAAAAAA AAAAAAA AAAAAAA AAAAAAA AAAAAAA ------- ------- -------