size = 6 3 14 
scale = 0.02
rotation = -90 0 25
position = 0 0.7 0

shell = Shell 0.5
material type = normal, lighting = smooth, side = back
  colors = Shell:#FFF
  
material lighting = both, wireframe = false, roughness = 0.2, metalness = 1, deform = 5,         colors = A:#FA0
material lighting = both, wireframe = false, roughness = 0.2, metalness = 1, deform = 10 1 0.75, colors = B:#FA0, clamp = y
material lighting = flat, wireframe = false, roughness = 0.2, metalness = 1, deform = 0,         colors = C:#FA0, clamp = y

voxels
--AA-- --AA-- --AA-- 
--AA-- CCAA-- --AA--
--AA-- -CAA-- --AA-- 
--AA-- CCAA-- --AA-- 
--AA-- --AA-- --AA-- 
--AA-- --AA-- --AA-- 
--AA-- --AA-- --AA-- 
--AA-- --AA-- --AA-- 
------ -BBBB- ------ 
------ BB--BB ------ 
------ B----B ------ 
------ B----B ------ 
------ BB--BB ------ 
------ -BBBB- ------