light color = #FFF 0.66
light direction = 1 1 0, color = #FFF 0.66
model
size = 9 13 29
scale = 0.066 0.066 0.066
origin = -y
skip = -y
material type = basic, lighting = flat, deform = 3 1, scatter = 0.5, fade = true//, skip = -y
  colors = B(232):#040 C(231):#050 D(230):#060 E(229):#070 F(228):#080 G(227):#090 H(226):#0A0
material type = basic, lighting = both, fade = true
  colors = A(96):#640 
voxels
--------- ---BBB--- ---BBB--- ----C---- ---------  --------- --------- --------- --------- --------- --------- --------- --------- 
--------- --BBBBB-- --BBBBB-- ---CCC--- ----C----  ----D---- --------- --------- --------- --------- --------- --------- --------- 
--------- -BBBBBBB- -BBBBBBB- --CCCCC-- ---CCC---  ---DDD--- ----D---- ----E---- ----E---- --------- --------- --------- --------- 
--------- BBB---BBB BBBBBBBBB -CCCCCCC- --CCCCC--  --DDDDD-- ---DDD--- ---EEE--- ---EEE--- ----F---- ----F---- ----F---- --------- 
----A---- BBB-A-BBB BBBBBBBBB CCCCCCCCC -CCCCCCC-  -DDDDDDD- --DDDDD-- --EEEEE-- --EEEEE-- ---FFF--- ---FFF--- ---FFF--- ----F---- 
--------- BBB---BBB BBBBBBBBB -CCCCCCC- --CCCCC--  --DDDDD-- ---DDD--- ---EEE--- ---EEE--- ----F---- ----F---- ----F---- --------- 
--------- -BBBBBBB- -BBBBBBB- --CCCCC-- ---CCC---  ---DDD--- ----D---- ----E---- ----E---- --------- --------- --------- --------- 
--------- --BBBBB-- --BBBBB-- ---CCC--- ----C----  ----D---- --------- --------- --------- --------- --------- --------- ---------
--------- ---BBB--- ---BBB--- ----C---- ---------  --------- --------- --------- --------- --------- --------- --------- --------- 
--------- --------- --------- --------- --------- --------- --------- --------- --------- --------- --------- --------- ---------  
--------- ---BBB--- ---CCC--- --------- --------- --------- --------- --------- --------- --------- --------- --------- ---------  
--------- --BBBBB-- --CCCCC-- ---DDD--- ---EEE--- ----F---- ----F---- --------- --------- --------- --------- --------- ---------  
--------- -BB---BB- -CCCCCCC- --DDDDD-- --EEEEE-- ---FFF--- ---FFF--- ----G---- ----G---- ----G---- --------- --------- ---------  
----A---- -BB-A-BB- -CCCCCCC- --DDDDD-- --EEEEE-- --FFFFF-- --FFFFF-- ---GGG--- ---GGG--- ---GGG--- ----G---- --------- ---------  
--------- -BB---BB- -CCCCCCC- --DDDDD-- --EEEEE-- ---FFF--- ---FFF--- ----G---- ----G---- ----G---- --------- --------- ---------  
--------- --BBBBB-- --CCCCC-- ---DDD--- ---EEE--- ----F---- ----F---- --------- --------- --------- --------- --------- ---------  
--------- ---BBB--- ---CCC--- --------- --------- --------- --------- --------- --------- --------- --------- --------- ---------
--------- --------- --------- --------- --------- --------- --------- --------- --------- --------- --------- --------- ---------  
--------- ---CCC--- ---DDD--- ---EEE--- ----F---- --------- --------- --------- --------- --------- --------- --------- ---------  
--------- --C---C-- --DDDDD-- --EEEEE-- ---FFF--- ----G---- ----H---- ----H---- --------- --------- --------- --------- --------- 
----A---- --C-A-C-- --DDDDD-- --EEEEE-- --FFFFF-- ---GGG--- ---HHH--- ---HHH--- ----H---- --------- --------- --------- ---------  
--------- --C---C-- --DDDDD-- --EEEEE-- ---FFF--- ----G---- ----H---- ----H---- --------- --------- --------- --------- --------- 
--------- ---CCC--- ---DDD--- ---EEE--- ----F---- --------- --------- --------- --------- --------- --------- --------- --------- 
--------- --------- --------- --------- --------- --------- --------- --------- --------- --------- --------- --------- --------- 
--------- ----E---- ----F---- --------- --------- --------- --------- --------- --------- --------- --------- --------- --------- 
--------- ---E-E--- ---FFF--- ----G---- ----H---- ----H---- --------- --------- --------- --------- --------- --------- --------- 
----A---- --E-A-E-- --FFFFF-- ---GGG--- ---HHH--- ---HHH--- ----H---- --------- --------- --------- --------- --------- ---------  
--------- ---E-E--- ---FFF--- ----G---- ----H---- ----H---- --------- --------- --------- --------- --------- --------- ---------
--------- ----E---- ----F---- --------- --------- --------- --------- --------- --------- --------- --------- --------- ---------