model
size = 28 13 13
scale = 0.03 0.03 0.03
origin = -y
ao = 1 0.75
material lighting = flat, deform = 1, roughness = 0.5
  colors = A:#444  C:#3CF E:#222
material lighting = flat
  colors = B:#666 
material lighting = both, deform = 2, clamp = y
  colors = D:#600
material lighting = both, deform = 2, clamp = -y
  colors = M:#444 N:#666 
voxels
---------------------------- ---------------------------- AAAAAAAAAAAAAAAAAAA--------- 9(AAAAAAAAACAAAAAAAAA---------) AAAAAAAAAAAAAAAAAAA---------
---------------------------- ---------------------------- AAAAAAAAAAAAAAAAAAA--------- 9(ACCCCCCCCCCCCCCCCCA---------) AAAAAAAAAEAAAAAAAAA---------
AAAAAAAAAAAAAAAAAAA--------- AAAAAAAAAAAAAAAAAAA--------- ---------------------------- 9(----------------------------) ----------------------------
-AAAAAAAAAAAAAAAAAA--------- AAAAAAAAAAAAAAAAAAA--------- -B-B-B-B-B-B-B-B-B---------- 9(----------------------------) ----------------------------
AAAAAAAAAAAAAAAAAAA--------- AAAAAAAAAAAAAAAAAAA--------- ---------------------------- 9(----------------------------) ----------------------------
-AAAAAAAAAAAAAAAAAA--------- AAAAAAAAAAAAAAAAAAA--------- -BB-B-B-B-B-B-B-BB---------- 9(----------------------------) ----------------------------
AAAAAAAAAAAAAAAAAAA-DDDDDDDD AAAAAAAAAAAAAAAAAAA--------- ---------------------------- 9(----------------------------) ----------------------------
-AAAAAAAAAAAAAAAAAA-DDDDDDDD AAAAAAAAAAAAAAAAAAA--------- -BB-B-BBBBBBB-B-BB---------- 9(----------------------------) ----------------------------
AAAAAAAAAAAAAAAAAAA-DDDDDDDD AAAAAAAAAAAAAAAAAAA---MMM--- ----------------------NMN--- 9(----------------------------) ----------------------------
AAAAAAAAAAAAAAAAAAA-DDDDDDDD AAAAAAAEEEEEAAAAAAA---MMM--- ----------------------NMN--- 9(----------------------------) ----------------------------
AAAAAAAAAAAAAAAAAAA-DDDDDDDD AAAAAAAEEEEEAAAAAAA---MMM--- ----------------------MMM--- 9(----------------------------) ----------------------------
AAAAAAAAAAAAAAAAAAA-DDDDDDDD AAAAAAAEEEEEAAAAAAA---MMM--- ----------------------MMM--- 9(----------------------------) ----------------------------
AAAAAAAAAAAAAAAAAAA-DDDDDDDD AAAAAAAAAAAAAAAAAAA--------- ---------------------------- 9(----------------------------) ----------------------------